ERROR    processes.cluster:cluster.py:77 Failed to cluster record <MagicMock id='140097224780096'>
Traceback (most recent call last):
  File "/home/runner/work/drb-etl-pipeline/drb-etl-pipeline/processes/cluster.py", line 73, in cluster_records
    work, stale_work_ids = self.cluster_record(unclustered_record)
  File "/opt/hostedtoolcache/Python/3.9.20/x64/lib/python3.9/unittest/mock.py", line 1092, in __call__
    return self._mock_call(*args, **kwargs)
  File "/opt/hostedtoolcache/Python/3.9.20/x64/lib/python3.9/unittest/mock.py", line 1096, in _mock_call
    return self._execute_mock_call(*args, **kwargs)
  File "/opt/hostedtoolcache/Python/3.9.20/x64/lib/python3.9/unittest/mock.py", line 1155, in _execute_mock_call
    raise result
processes.cluster.ClusterError