{"timestamp":1729691672743,"message":"Unable to cluster record <MagicMock id='139778731864016'>","log.level":"ERROR","logger.name":"processes.cluster","thread.id":139779400858496,"thread.name":"MainThread","process.id":2361,"process.name":"MainProcess","file.name":"/home/runner/work/drb-etl-pipeline/drb-etl-pipeline/processes/cluster.py","line.number":111,"entity.type":"SERVICE","error.class":"sqlalchemy.exc:DataError","error.message":"(builtins.str) testing\n[SQL: test]\n(Background on this error at: https://sqlalche.me/e/20/9h9h)"}
