{"timestamp":1730405783422,"message":"Failed to cluster record <MagicMock id='139788012164336'>","log.level":"ERROR","logger.name":"processes.cluster","thread.id":139788675943296,"thread.name":"MainThread","process.id":2464,"process.name":"MainProcess","file.name":"/home/runner/work/drb-etl-pipeline/drb-etl-pipeline/processes/cluster.py","line.number":83,"entity.type":"SERVICE","error.class":"processes.cluster:ClusterError","error.message":""}
