ERROR    processes.file.s3_files:s3_files.py:118 Failed to get file contents from testURL
Traceback (most recent call last):
  File "/home/runner/work/drb-etl-pipeline/drb-etl-pipeline/processes/file/s3_files.py", line 109, in get_file_contents
    file_url_response.raise_for_status()
  File "/opt/hostedtoolcache/Python/3.9.20/x64/lib/python3.9/unittest/mock.py", line 1092, in __call__
    return self._mock_call(*args, **kwargs)
  File "/opt/hostedtoolcache/Python/3.9.20/x64/lib/python3.9/unittest/mock.py", line 1096, in _mock_call
    return self._execute_mock_call(*args, **kwargs)
  File "/opt/hostedtoolcache/Python/3.9.20/x64/lib/python3.9/unittest/mock.py", line 1151, in _execute_mock_call
    raise effect
Exception