ERROR    processes.ingest.hathi_trust:hathi_trust.py:93 Unable to read Hathi Trust file url badURL
Traceback (most recent call last):
  File "/home/runner/work/drb-etl-pipeline/drb-etl-pipeline/processes/ingest/hathi_trust.py", line 91, in importFromHathiFile
    hathiResp.raise_for_status()
  File "/opt/hostedtoolcache/Python/3.9.20/x64/lib/python3.9/unittest/mock.py", line 1092, in __call__
    return self._mock_call(*args, **kwargs)
  File "/opt/hostedtoolcache/Python/3.9.20/x64/lib/python3.9/unittest/mock.py", line 1096, in _mock_call
    return self._execute_mock_call(*args, **kwargs)
  File "/opt/hostedtoolcache/Python/3.9.20/x64/lib/python3.9/unittest/mock.py", line 1151, in _execute_mock_call
    raise effect
requests.exceptions.HTTPError